<?xml version="1.0" encoding="utf-8"?>
<!-- =================================================================================== -->
<!-- |    This document was autogenerated by xacro from ../../ws_moveit/src/reemc_robot/reemc_description/robots/reemc_full_ft_hey5.urdf.xacro | -->
<!-- |    EDITING THIS FILE BY HAND IS NOT RECOMMENDED                                 | -->
<!-- =================================================================================== -->
<!--

  Copyright (c) 2014, PAL Robotics, S.L.
  All rights reserved.

  This work is licensed under the Creative Commons Attribution-NonCommercial-NoDerivs 3.0 Unported License.
  To view a copy of this license, visit http://creativecommons.org/licenses/by-nc-nd/3.0/ or send a letter to
  Creative Commons, 444 Castro Street, Suite 900, Mountain View, California, 94041, USA.
-->
<robot name="reemc" xmlns:controller="http://playerstage.sourceforge.net/gazebo/xmlschema/#controller" xmlns:interface="http://playerstage.sourceforge.net/gazebo/xmlschema/#interface" xmlns:sensor="http://playerstage.sourceforge.net/gazebo/xmlschema/#sensor">
    <link name="world">
  </link>
  <joint name="Fix_world" type="fixed">
    <parent link="world" />
    <child link="base_link" />
  </joint>
  
  <link name="base_link">
  </link>
  <link name="base_linkx">
  </link>
  <link name="base_linkxx">
  </link>
  <joint name="world_joint" type="prismatic">
    <axis xyz="0 0 -1"/>
    <parent link="base_link"/>
    <child link="base_linkx"/>
    <origin rpy="0.0 0.0 0.0" xyz="0.0 0.0 0.0"/>
    <limit effort="140.4" lower="-2" upper="2" velocity="3.225"/>
  </joint>
  <joint name="world_joint2" type="prismatic">
    <axis xyz="0 1 0"/>
    <parent link="base_linkx"/>
    <child link="base_linkxx"/>
    <origin rpy="0.0 0.0 0.0" xyz="0.0 0.0 0.0"/>
    <limit effort="140.4" lower="0" upper="0" velocity="3.225"/>
  </joint>
  <joint name="world_joint3" type="prismatic">
    <axis xyz="1 0 0"/>
    <parent link="base_linkxx"/>
    <child link="base_link2"/>
    <origin rpy="0.0 0.0 0.0" xyz="0.0 0.0 0.0"/>
    <limit effort="140.4" lower="-2" upper="2" velocity="3.225"/>
  </joint>
  <link name="base_link2">
    <!-- <visual>
      <origin rpy="0 0 0" xyz="0 0 0"/>
      <geometry>
        <mesh filename="package://reemc_description/meshes/base/base.dae"/>
      </geometry>
      
    </visual>
    <collision>
      <origin rpy="0 0 0" xyz="-0.022 0 0.01"/>
      <geometry>
        <box size="0.3 0.35 0.14"/>
      </geometry>
    </collision> -->
  </link>
  <!-- TODO: Update dynamic models -->
  <!-- TODO: Update dynamic models -->

  <!-- attach optical frame to the camera link -->
  <!-- optical frame for the stereo camera, with z-forward notation, this is the frame stereo camera images users should refer to -->
  <!-- Now we can start using the macros included above to define the actual robot -->
  <!-- The reflect parameter takes the value 1 or -1 to respectively distinguish right from left side in expressions -->
  <!--************************-->
  <!--        TORSO_1         -->
  <!--************************-->
  <link name="torso_1_link">
    <inertial>
      <origin rpy="0 0 0" xyz="-0.00011 -0.00002 -0.00669"/>
      <mass value="1.58341"/>
      <!-- NOTE: Assuming cylinder with length="0.295" radius="0.0465-->
      <inertia ixx="0.0036591855" ixy="0.00000036753" ixz="0.00000297759" iyy="0.00115955355" iyz="0.00000024742" izz="0.00360440105"/>
    </inertial>
    <visual>
      <origin rpy="1.57079632679 0 0" xyz="0 0 0"/>
      <geometry>
        <cylinder length="0.15" radius="0.0465"/>
      </geometry>
      
    </visual>
  </link>
  <joint name="torso_1_joint" type="fixed">
    <parent link="base_link2"/>
    <child link="torso_1_link"/>
    <origin rpy="0 0 0" xyz="0 0 0.14353"/>
    <axis xyz="0 0 1"/>
    <limit effort="78.0" lower="-1.308996939" upper="1.308996939" velocity="5.4"/>
    <dynamics damping="1.0" friction="1.0"/>
    <safety_controller k_position="20" k_velocity="20" soft_lower_limit="-1.25409035396" soft_upper_limit="1.25409035396"/>
  </joint>
  <!--************************-->
  <!--        TORSO_2         -->
  <!--************************-->
  <link name="torso_2_link">
    <inertial>
      <origin rpy="0 0 0" xyz="-0.01816 -0.17956 -0.00103"/>
      <mass value="11.18103"/>
      <!-- NOTE: Assuming box with d=0.2, w=0.295, h=0.254 -->
      <inertia ixx="0.159836691" ixy="-0.00377573015" ixz="0.00094280162" iyy="0.08484637595" iyz="0.00020220508" izz="0.13253975464"/>
    </inertial>
    <visual>
      <origin rpy="0 0 0" xyz="0 0 0"/>
      <geometry>
        <mesh filename="package://reemc_description/meshes/torso/torso_2.dae"/>
      </geometry>
      
    </visual>
    <collision>
      <origin rpy="0 0 0" xyz="0 0 0"/>
      <geometry>
        <mesh filename="package://reemc_description/meshes/torso/torso_2_collision.stl"/>
      </geometry>
    </collision>
  </link>
  <joint name="torso_2_joint" type="fixed">
    <parent link="torso_1_link"/>
    <child link="torso_2_link"/>
    <origin rpy="-1.57079632679 0 0" xyz="0 0 0"/>
    <axis xyz="0 0 1"/>
    <limit effort="78.0" lower="-0.261799387799" upper="2.09439510239" velocity="5.4"/>
    <dynamics damping="1.0" friction="1.0"/>
    <safety_controller k_position="20" k_velocity="20" soft_lower_limit="-0.206892802759" soft_upper_limit="2.07439510239"/>
  </joint>
  <link name="head_1_link">
    <inertial>
      <origin rpy="0 0 0" xyz="0.01819 0.00248 -0.00517"/>
      <mass value="1.11967"/>
      <!-- NOTE: Assuming cylinder with r=0.06, h=0.08 -->
      <!--         <inertia ixx="0.0014125"  ixy="0"  ixz="0" iyy="0.0014125" iyz="0" izz="0.0017738" /> -->
      <inertia ixx="0.00111370229" ixy="0.00003992198" ixz="-0.00012464155" iyy="0.00111361487" iyz="0.00001943162" izz="0.00114794061"/>
    </inertial>
    <visual>
      <origin rpy="0 0 0" xyz="-0.03 0 0"/>
      <!--TODO: Remove offset when good meshes arrive-->
      <geometry>
        <mesh filename="package://reemc_description/meshes/head/head_1.dae"/>
      </geometry>
      
    </visual>
    <collision>
      <origin rpy="0 0 0" xyz="-0.03 0 0"/>
      <geometry>
        <mesh filename="package://reemc_description/meshes/head/head_1_collision.stl"/>
      </geometry>
    </collision>
  </link>
  <joint name="head_1_joint" type="fixed">
    <parent link="torso_2_link"/>
    <child link="head_1_link"/>
    <origin rpy="1.57079632679 0 0" xyz="0.0 -0.42316 0"/>
    <axis xyz="0 0 1"/>
    <limit effort="3.4" lower="-1.308996939" upper="1.308996939" velocity="3.0"/>
    <dynamics damping="0.5" friction="1.0"/>
    <safety_controller k_position="20" k_velocity="20" soft_lower_limit="-1.25409035396" soft_upper_limit="1.25409035396"/>
  </joint>
  <link name="head_2_link">
    <inertial>
      <origin rpy="0 0 0" xyz="0.01183 -0.08098 0.00104"/>
      <mass value="1.63134"/>
      <!-- NOTE: Assuming box with d=0.28433, w=0.20302, h=0.26741 -->
      <!--         <inertia ixx="0.011353"  ixy="0"  ixz="0" iyy="0.012294" iyz="0" izz="0.015345" /> -->
      <!--NOTE: Low (0.1 or lower) diagonal inertia values make Gazebo 1.0.2 simulation unstable when head sensors are added.-->
      <inertia ixx="0.00640199093" ixy="0.00012197067" ixz="-0.00000897011" iyy="0.00676228591" iyz="-0.0000552329" izz="0.00614192438"/>
    </inertial>
    <visual>
      <origin rpy="0 0 0" xyz="-0.03 0 0"/>
      <!--TODO: Remove offset when good meshes arrive-->
      <geometry>
        <mesh filename="package://reemc_description/meshes/head/head_2_v0.dae"/>
      </geometry>
      
    </visual>
    <collision>
      <origin rpy="0 0 0" xyz="-0.03 0 0"/>
      <geometry>
        <mesh filename="package://reemc_description/meshes/head/head_2_collision.stl"/>
      </geometry>
    </collision>
  </link>
  <joint name="head_2_joint" type="fixed">
    <parent link="head_1_link"/>
    <child link="head_2_link"/>
    <origin rpy="-1.57079632679 0 0" xyz="0.0445 0 0"/>
    <axis xyz="0 0 1"/>
    <limit effort="3.26" lower="-0.261799387799" upper="0.785398163397" velocity="3.0"/>
    <dynamics damping="0.5" friction="1.0"/>
    <safety_controller k_position="20" k_velocity="20" soft_lower_limit="-0.206892802759" soft_upper_limit="0.750491578358"/>
  </joint>
  <!--************************-->
  <!--        SHOULDER        -->
  <!--************************-->
  <link name="arm_right_1_link">
    <inertial>
      <origin rpy="0 0 0" xyz="0.00701 -0.00011 0.18627"/>
      <mass value="1.53614"/>
      <!--        <inertia ixx="0"  ixy="0"  ixz="0" iyy="0" iyz="0" izz="0" /> -->
      <!--         NOTE: Assuming cylinder centered at CoM with r=0.05, h=0.05 with axis parallel to x coordinate -->
      <!--        <inertia ixx="0.0026850"  ixy="0"  ixz="0" iyy="0.0017900" iyz="0" izz="0.0017900" /> -->
      <inertia ixx="0.00327313329" ixy="-0.00000460054" ixz="-0.00025121368" iyy="0.00316047802" iyz="0.00000313158" izz="0.00157642528"/>
    </inertial>
    <visual>
      <origin rpy="0 0 0" xyz="0 0 0"/>
      <geometry>
        <mesh filename="package://reemc_description/meshes/arm/arm_1.dae" scale="1 1 -1.0"/>
      </geometry>
      
    </visual>
    <collision>
      <origin rpy="0 0 0" xyz="0 0 0"/>
      <geometry>
        <mesh filename="package://reemc_description/meshes/arm/arm_1_collision.stl" scale="1 1 -1.0"/>
      </geometry>
    </collision>
  </link>
  <joint name="arm_right_1_joint" type="revolute">
    <parent link="torso_2_link"/>
    <child link="arm_right_1_link"/>
    <origin rpy="-2.87979326579 0 0" xyz="0 -0.31827 0"/>
    <axis xyz="0 0 1"/>
    <limit effort="44.64" lower="-0.785398163397" upper="3.14159265359" velocity="2.7"/>
    <dynamics damping="1.0" friction="1.0"/>
    <safety_controller k_position="20" k_velocity="20" soft_lower_limit="-0.730491578358" soft_upper_limit="3.08668606855"/>
  </joint>
  <link name="arm_right_2_link">
    <inertial>
      <origin rpy="0 0 0" xyz="0.01435 -0.06294 0.01039"/>
      <mass value="1.60393"/>
      <!--<inertia ixx="0"  ixy="0"  ixz="0" iyy="0" iyz="0" izz="0" />-->
      <!-- NOTE: Assuming cylinder centered at CoM with r=0.05, h=0.05 with axis parallel to y coordinate -->
      <!-- <inertia ixx="0.0013417"  ixy="0"  ixz="0" iyy="0.0020125" iyz="0" izz="0.0013417" /> -->
      <inertia ixx="0.0046195621" ixy="-0.00056769245" ixz="0.00018376961" iyy="0.00185384237" iyz="-0.00078286958" izz="0.0049356022"/>
    </inertial>
    <visual>
      <origin rpy="0 0 0" xyz="0 0 0"/>
      <geometry>
        <mesh filename="package://reemc_description/meshes/arm/arm_2.dae" scale="1 1 -1.0"/>
      </geometry>
      
    </visual>
    <collision>
      <origin rpy="0 0 0" xyz="0 0 0"/>
      <geometry>
        <mesh filename="package://reemc_description/meshes/arm/arm_2_collision.stl" scale="1 1 -1.0"/>
      </geometry>
    </collision>
  </link>
  <joint name="arm_right_2_joint" type="revolute">
    <parent link="arm_right_1_link"/>
    <child link="arm_right_2_link"/>
    <origin rpy="-1.57079632679 -1.308996939 1.57079632679" xyz="0 0 0.21749"/>
    <axis xyz="0 0 1"/>
    <limit effort="22.32" lower="-0.261799387799" upper="2.09439510239" velocity="3.66"/>
    <dynamics damping="1.0" friction="1.0"/>
    <safety_controller k_position="20" k_velocity="20" soft_lower_limit="-0.206892802759" soft_upper_limit="2.03948851735"/>
  </joint>
  <link name="arm_right_3_link">
    <inertial>
      <origin rpy="0 0 0" xyz="0.00606 -0.0113 0.05748"/>
      <mass value="1.64293"/>
      <!--<inertia ixx="0"  ixy="0"  ixz="0" iyy="0" iyz="0" izz="0" />-->
      <!-- NOTE: Assuming cylinder centered at CoM with r=0.05, h=0.05 with axis parallel to x coordinate -->
      <inertia ixx="0.00372686652" ixy="-0.00008722874" ixz="-0.00028800176" iyy="0.00344463026" iyz="0.00042776588" izz="0.00192229026"/>
    </inertial>
    <visual>
      <origin rpy="0 0 0" xyz="0 0 0"/>
      <geometry>
        <mesh filename="package://reemc_description/meshes/arm/arm_3.dae" scale="1 1 -1.0"/>
      </geometry>
      
    </visual>
    <collision>
      <origin rpy="0 0 0" xyz="0 0 0"/>
      <geometry>
        <mesh filename="package://reemc_description/meshes/arm/arm_3_collision.stl" scale="1 1 -1.0"/>
      </geometry>
    </collision>
  </link>
  <joint name="arm_right_3_joint" type="revolute">
    <parent link="arm_right_2_link"/>
    <child link="arm_right_3_link"/>
    <origin rpy="1.57079632679 0 0" xyz="0.02 -0.142 0"/>
    <axis xyz="0 0 1"/>
    <limit effort="17.86" lower="-2.35619449019" upper="2.74889357189" velocity="4.58"/>
    <dynamics damping="1.0" friction="1.0"/>
    <safety_controller k_position="20" k_velocity="20" soft_lower_limit="-2.30128790515" soft_upper_limit="2.69398698685"/>
  </joint>
  <!--************************-->
  <!--        ELBOW           -->
  <!--************************-->
  <link name="arm_right_4_link">
    <inertial>
      <origin rpy="0 0 0" xyz="-0.04129 0.0118 -0.01387"/>
      <mass value="1.20222"/>
      <!--<inertia ixx="0"  ixy="0"  ixz="0" iyy="0" iyz="0" izz="0" />-->
      <!-- NOTE: Assuming cylinder centered at CoM with r=0.05, h=0.05 with axis parallel to x coordinate -->
      <!-- <inertia ixx="0.0012663"  ixy="0"  ixz="0" iyy="0.00084417" iyz="0" izz="0.00084417" /> -->
      <inertia ixx="0.00156355749" ixy="-0.000353141" ixz="0.00053402452" iyy="0.00277186194" iyz="-0.00015541973" izz="0.00307369106"/>
    </inertial>
    <visual>
      <origin rpy="0 0 0" xyz="0 0 0"/>
      <geometry>
        <mesh filename="package://reemc_description/meshes/arm/arm_4.dae" scale="1 1 -1.0"/>
      </geometry>
      
    </visual>
    <collision>
      <origin rpy="0 0 0" xyz="0 0 0"/>
      <geometry>
        <mesh filename="package://reemc_description/meshes/arm/arm_4_collision.stl" scale="1 1 -1.0"/>
      </geometry>
    </collision>
  </link>
  <joint name="arm_right_4_joint" type="revolute">
    <parent link="arm_right_3_link"/>
    <child link="arm_right_4_link"/>
    <origin rpy="0 1.57079632679 0" xyz="0 -0.02 0.088"/>
    <axis xyz="0 0 1"/>
    <limit effort="17.86" lower="0" upper="2.26892802759" velocity="4.58"/>
    <dynamics damping="1.0" friction="1.0"/>
    <safety_controller k_position="20" k_velocity="20" soft_lower_limit="0.0549065850399" soft_upper_limit="2.21402144255"/>
  </joint>
  <!--************************-->
  <!--        WRIST           -->
  <!--************************-->
  <link name="arm_right_5_link">
    <inertial>
      <origin rpy="0 0 0" xyz="-0.00044 0.00012 0.07445"/>
      <mass value="1.21524"/>
      <!-- <inertia ixx="0"  ixy="0"  ixz="0" iyy="0" iyz="0" izz="0" /> -->
      <!-- NOTE: Assuming cylinder centered at CoM with r=0.05, h=0.1 with axis parallel to z coordinate -->
      <!--         <inertia ixx="0.0027096"  ixy="0"  ixz="0" iyy="0.0027096" iyz="0" izz="0.0023225" /> -->
      <inertia ixx="0.00193499547" ixy="-0.00000027528" ixz="-0.00001268153" iyy="0.00177767506" iyz="-0.00000466638" izz="0.00057101196"/>
    </inertial>
    <visual>
      <origin rpy="0 0 0" xyz="0 0 0"/>
      <geometry>
        <mesh filename="package://reemc_description/meshes/arm/arm_5.dae" scale="1 1 -1.0"/>
      </geometry>
      
    </visual>
    <collision>
      <origin rpy="0 0 0" xyz="0 0 0"/>
      <geometry>
        <mesh filename="package://reemc_description/meshes/arm/arm_5_collision.stl" scale="1 1 -1.0"/>
      </geometry>
    </collision>
  </link>
  <joint name="arm_right_5_joint" type="revolute">
    <parent link="arm_right_4_link"/>
    <child link="arm_right_5_link"/>
    <origin rpy="0 -1.57079632679 0" xyz="-0.088 0.02 0"/>
    <axis xyz="0 0 1"/>
    <limit effort="3" lower="-2.09439510239" upper="2.09439510239" velocity="1.95"/>
    <!--TODO: Check effort value!-->
    <dynamics damping="1.0" friction="1.0"/>
    <safety_controller k_position="20" k_velocity="20" soft_lower_limit="-2.03948851735" soft_upper_limit="2.03948851735"/>
  </joint>
  <link name="arm_right_6_link">
    <inertial>
      <origin rpy="0 0 0" xyz="-0.00005 -0.00252 7e-05"/>
      <mass value="0.41597"/>
      <!-- <inertia ixx="0"  ixy="0"  ixz="0" iyy="0" iyz="0" izz="0" /> -->
      <!-- NOTE: Assuming cylinder centered at CoM with r=0.02, h=0.08 with axis parallel to z coordinate -->
      <!--         <inertia ixx="0.0001615"  ixy="0"  ixz="0" iyy="0.0001615" iyz="0" izz="0.000051" /> -->
      <inertia ixx="0.00020339659" ixy="-0.00000071703" ixz="-0.00000006654" iyy="0.00015240261" iyz="0.00000014315" izz="0.0001671881"/>
    </inertial>
    <visual>
      <origin rpy="0 0 0" xyz="0 0 0"/>
      <geometry>
        <mesh filename="package://reemc_description/meshes/arm/arm_6.dae" scale="1 1 -1.0"/>
      </geometry>
      
    </visual>
    <collision>
      <origin rpy="0 0 0" xyz="0 0 0"/>
      <geometry>
        <cylinder length="0.0385" radius="0.04"/>
      </geometry>
    </collision>
  </link>
  <joint name="arm_right_6_joint" type="revolute">
    <parent link="arm_right_5_link"/>
    <child link="arm_right_6_link"/>
    <origin rpy="-1.57079632679 0 0" xyz="0 0 0.15"/>
    <axis xyz="0 0 1"/>
    <limit effort="6.6" lower="-1.41371669412" upper="1.41371669412" velocity="1.76"/>
    <dynamics damping="1.0" friction="1.0"/>
    <safety_controller k_position="20" k_velocity="20" soft_lower_limit="-1.42862327916" soft_upper_limit="1.35881010908"/>
  </joint>
  <link name="arm_right_7_link">
    <inertial>
      <!--TODO: Verify these inertial parameters-->
      <origin rpy="0 0 0" xyz="-0.00004 0 -0.02887"/>
      <mass value="0.06697"/>
      <!-- <inertia ixx="0"  ixy="0"  ixz="0" iyy="0" iyz="0" izz="0" /> -->
      <!-- NOTE: Assuming point mass -->
      <!--         <inertia ixx="0"  ixy="0"  ixz="0" iyy="0" iyz="0" izz="0" /> -->
      <inertia ixx="0.0000123718" ixy="0.00000000002" ixz="0.00000002403" iyy="0.00001242132" iyz="0.00000000001" izz="0.0000059514"/>
    </inertial>
    <visual>
      <origin rpy="0 0 0" xyz="0 0 0.046"/>
      <geometry>
        <cylinder length="0.005" radius="0.02"/>
      </geometry>
      
    </visual>
    <collision>
      <origin rpy="0 0 0" xyz="0 0 0.0345"/>
      <geometry>
        <cylinder length="0.023" radius="0.02"/>
      </geometry>
    </collision>
  </link>
  <joint name="arm_right_7_joint" type="revolute">
    <parent link="arm_right_6_link"/>
    <child link="arm_right_7_link"/>
    <origin rpy="1.57079632679 0 0" xyz="0 0 0"/>
    <axis xyz="0 0 1"/>
    <limit effort="6.6" lower="-2.09439510239" upper="2.09439510239" velocity="1.76"/>
    <dynamics damping="1.0" friction="1.0"/>
    <safety_controller k_position="20" k_velocity="20" soft_lower_limit="-2.03948851735" soft_upper_limit="2.03948851735"/>
  </joint>
  <!--***********************-->
  <!--        TOOL           -->
  <!--***********************-->
  <link name="arm_right_tool_link">
    <inertial>
      <mass value="0.1"/>
      <inertia ixx="0.0" ixy="0.0" ixz="0.0" iyy="0.0" iyz="0.0" izz="0.0"/>
    </inertial>
    <visual>
      <origin rpy="0 1.57079632679 0" xyz="0.001 0 0"/>
      <geometry>
        <cylinder length="0.005" radius="0.005"/>
      </geometry>
      
    </visual>
    <collision>
      <origin rpy="0 1.57079632679 0" xyz="0.001 0 0"/>
      <geometry>
        <cylinder length="0.005" radius="0.005"/>
      </geometry>
    </collision>
  </link>
  <joint name="arm_right_tool_joint" type="fixed">
    <parent link="arm_right_7_link"/>
    <child link="arm_right_tool_link"/>
    <origin rpy="1.57079632679 -1.57079632679 0" xyz="0 0 0.046"/>
  </joint>
  <!--************************-->
  <!--        ft sensor       -->
  <!--************************-->
  <link name="wrist_right_ft_link">
    <inertial>
      <mass value="0.1"/>
      <inertia ixx="0.0" ixy="0.0" ixz="0.0" iyy="0.0" iyz="0.0" izz="0.0"/>
    </inertial>
    <visual>
      <origin rpy="0 0 0" xyz="0 0 0"/>
      <geometry>
        <cylinder length="0.0157" radius="0.0225"/>
      </geometry>
      
    </visual>
    <collision>
      <origin rpy="0 0 0" xyz="0 0 0"/>
      <geometry>
        <cylinder length="0.0157" radius="0.0225"/>
      </geometry>
    </collision>
  </link>
  <joint name="wrist_right_ft_joint" type="fixed">
    <parent link="arm_right_tool_link"/>
    <child link="wrist_right_ft_link"/>
    <origin rpy="1.57079632679 0 1.57079632679" xyz="0.00785 0 0"/>
  </joint>
  <!--***********************-->
  <!--       FT TOOL         -->
  <!--***********************-->
  <link name="wrist_right_ft_tool_link">
    <inertial>
      <mass value="0.1"/>
      <inertia ixx="0.0" ixy="0.0" ixz="0.0" iyy="0.0" iyz="0.0" izz="0.0"/>
    </inertial>
    <visual>
      <origin rpy="0 1.57079632679 0" xyz="0.0 0 0"/>
      <geometry>
        <cylinder length="0.00975" radius="0.025"/>
      </geometry>
      
    </visual>
    <collision>
      <origin rpy="0 1.57079632679 0" xyz="0.0 0 0"/>
      <geometry>
        <cylinder length="0.00975" radius="0.025"/>
      </geometry>
    </collision>
  </link>
  <joint name="wrist_right_tool_joint" type="fixed">
    <parent link="wrist_right_ft_link"/>
    <child link="wrist_right_ft_tool_link"/>
    <origin rpy="-1.57079632679 -1.57079632679 0" xyz="0 0 0.012725"/>
  </joint>
  <!-- <xacro:ft_sensor name="wrist" parent="arm_left_tool_link"  side="left"  reflect="-1.0" /> -->
  <!-- Tool Link -->
  <link name="hand_right_tool_link">
    <inertial>
      <origin rpy="0 0 0" xyz="0 0 0"/>
      <mass value="0.0001"/>
      <inertia ixx="0.00001" ixy="0.0" ixz="0.0" iyy="0.00001" iyz="0.0" izz="0.00001"/>
    </inertial>
  </link>
  <joint name="hand_right_tool_joint" type="fixed">
    <origin rpy="0 0 0" xyz="0 0 0"/>
    <parent link="wrist_right_ft_tool_link"/>
    <child link="hand_right_tool_link"/>
    <axis xyz="0 0 0"/>
  </joint>
  <joint name="hand_right_palm_joint" type="fixed">
    <parent link="wrist_right_ft_tool_link"/>
    <child link="hand_right_palm_link"/>
    <origin rpy="0 0 0" xyz="0 0 0"/>
  </joint>
  <link name="hand_right_palm_link">
    <inertial>
      <origin rpy="0 0 0" xyz="0.0641 -0.0022 0.0021"/>
      <!-- NOTE: Less than total palm mass of 0.598kg because actuator masses are specified separately -->
      <mass value="0.4"/>
      <inertia ixx="0.000305100" ixy="0.000005037" ixz="0.000015302" iyy="0.000811920" iyz="0.000007622" izz="0.000655851"/>
    </inertial>
    <visual>
      <origin rpy="0 0 0" xyz="0 0 0"/>
      <geometry>
        <mesh filename="package://hey5_description/meshes/palm.stl" scale="1 1 1"/>
      </geometry>
      
    </visual>
    <collision>
      <origin rpy="0 0 0" xyz="0 0 0"/>
      <geometry>
        <mesh filename="package://hey5_description/meshes/palm_collision.stl" scale="1 1 1"/>
      </geometry>
    </collision>
  </link>
  <link name="hand_right_grasping_frame">
    <visual>
      <origin rpy="0 0 0" xyz="0 0 0"/>
      <geometry>
        <mesh filename="package://hey5_description/meshes/palm.stl" scale="1 1 1"/>
      </geometry>
      
    </visual>
    <collision>
      <origin rpy="0 0 0" xyz="0 0 0"/>
      <geometry>
        <mesh filename="package://hey5_description/meshes/palm_collision.stl" scale="0 0 0"/>
      </geometry>
    </collision>
  </link>
  <joint name="hand_right_grasping_joint" type="revolute">
    <parent link="hand_right_palm_link"/>
    <child link="hand_right_grasping_frame"/>
    <axis xyz="0 0 1"/>
    <limit effort="44.64" lower="-3.14159265359" upper="3.14159265359" velocity="2.7"/>
    <origin rpy="0 0 0" xyz="0 0 0"/>
  </joint>
  <!-- <xacro:hey5_hand parent="wrist_left_ft_tool_link" name="hand_left" reflect="-1" >
    <origin xyz="0 0 0" rpy="${180 * deg_to_rad} 0 0" />
  </xacro:hey5_hand> -->
  <!-- camera link is at center of the optical frame, but in x-forward, z-upwards and y-leftwards notation (required by gazebo to simulate a camera) -->
  <!-- attach optical frame to the camera link -->
    <klampt package_root="/mnt/2/sjm_env/ws_moveit/src/reemc_robot" />


 <noselfcollision group1="arm_right_1_link" group2="arm_right_2_link"  />
    <noselfcollision group1="arm_right_1_link" group2="arm_right_3_link"  />
    <noselfcollision group1="arm_right_1_link" group2="arm_right_4_link"  />
    <noselfcollision group1="arm_right_1_link" group2="arm_right_5_link"  />
    <noselfcollision group1="arm_right_1_link" group2="arm_right_6_link"  />
    <noselfcollision group1="arm_right_1_link" group2="arm_right_7_link"  />
    <noselfcollision group1="arm_right_1_link" group2="arm_right_tool_link"  />
    <noselfcollision group1="arm_right_1_link" group2="back_camera_gazebo_back_camera_link"  />
    <noselfcollision group1="arm_right_1_link" group2="back_camera_link"  />
    <noselfcollision group1="arm_right_1_link" group2="base_link2"  />
    <noselfcollision group1="arm_right_1_link" group2="head_1_link"  />
    <noselfcollision group1="arm_right_1_link" group2="head_2_link"  />
    <noselfcollision group1="arm_right_1_link" group2="imu_link"  />
    <noselfcollision group1="arm_right_1_link" group2="stereo_gazebo_left_camera_link"  />
    <noselfcollision group1="arm_right_1_link" group2="stereo_gazebo_right_camera_link"  />
    <noselfcollision group1="arm_right_1_link" group2="stereo_link"  />
    <noselfcollision group1="arm_right_1_link" group2="torso_1_link"  />
    <noselfcollision group1="arm_right_1_link" group2="torso_2_link"  />
    <noselfcollision group1="arm_right_1_link" group2="wrist_right_ft_link"  />
    <noselfcollision group1="arm_right_1_link" group2="wrist_right_ft_tool_link"  />
    <noselfcollision group1="arm_right_2_link" group2="arm_right_3_link"  />
    <noselfcollision group1="arm_right_2_link" group2="arm_right_4_link"  />
    <noselfcollision group1="arm_right_2_link" group2="arm_right_5_link"  />
    <noselfcollision group1="arm_right_2_link" group2="arm_right_6_link"  />
    <noselfcollision group1="arm_right_2_link" group2="arm_right_7_link"  />
    <noselfcollision group1="arm_right_2_link" group2="arm_right_tool_link"  />
    <noselfcollision group1="arm_right_2_link" group2="back_camera_gazebo_back_camera_link"  />
    <noselfcollision group1="arm_right_2_link" group2="back_camera_link"  />
    <noselfcollision group1="arm_right_2_link" group2="base_link2"  />
    <noselfcollision group1="arm_right_2_link" group2="head_1_link"  />
    <noselfcollision group1="arm_right_2_link" group2="head_2_link"  />
    <noselfcollision group1="arm_right_2_link" group2="imu_link"  />
    <noselfcollision group1="arm_right_2_link" group2="stereo_gazebo_left_camera_link"  />
    <noselfcollision group1="arm_right_2_link" group2="stereo_gazebo_right_camera_link"  />
    <noselfcollision group1="arm_right_2_link" group2="stereo_link"  />
    <noselfcollision group1="arm_right_2_link" group2="torso_1_link"  />
    <noselfcollision group1="arm_right_2_link" group2="torso_2_link"  />
    <noselfcollision group1="arm_right_2_link" group2="wrist_right_ft_link"  />
    <noselfcollision group1="arm_right_2_link" group2="wrist_right_ft_tool_link"  />
    <noselfcollision group1="arm_right_3_link" group2="arm_right_4_link"  />
    <noselfcollision group1="arm_right_3_link" group2="arm_right_5_link"  />
    <noselfcollision group1="arm_right_3_link" group2="arm_right_6_link"  />
    <noselfcollision group1="arm_right_3_link" group2="arm_right_7_link"  />
    <noselfcollision group1="arm_right_3_link" group2="arm_right_tool_link"  />
    <noselfcollision group1="arm_right_3_link" group2="back_camera_gazebo_back_camera_link"  />
    <noselfcollision group1="arm_right_3_link" group2="back_camera_link"  />
    <noselfcollision group1="arm_right_3_link" group2="head_1_link"  />
    <noselfcollision group1="arm_right_3_link" group2="head_2_link"  />
    <noselfcollision group1="arm_right_3_link" group2="imu_link"  />
    <noselfcollision group1="arm_right_3_link" group2="stereo_gazebo_left_camera_link"  />
    <noselfcollision group1="arm_right_3_link" group2="stereo_gazebo_right_camera_link"  />
    <noselfcollision group1="arm_right_3_link" group2="stereo_link"  />
    <noselfcollision group1="arm_right_3_link" group2="torso_1_link"  />
    <noselfcollision group1="arm_right_3_link" group2="wrist_right_ft_link"  />
    <noselfcollision group1="arm_right_3_link" group2="wrist_right_ft_tool_link"  />
    <noselfcollision group1="arm_right_4_link" group2="arm_right_5_link"  />
    <noselfcollision group1="arm_right_4_link" group2="arm_right_6_link"  />
    <noselfcollision group1="arm_right_4_link" group2="arm_right_7_link"  />
    <noselfcollision group1="arm_right_4_link" group2="arm_right_tool_link"  />
    <noselfcollision group1="arm_right_4_link" group2="back_camera_gazebo_back_camera_link"  />
    <noselfcollision group1="arm_right_4_link" group2="back_camera_link"  />
    <noselfcollision group1="arm_right_4_link" group2="head_1_link"  />
    <noselfcollision group1="arm_right_4_link" group2="head_2_link"  />
    <noselfcollision group1="arm_right_4_link" group2="imu_link"  />
    <noselfcollision group1="arm_right_4_link" group2="stereo_gazebo_left_camera_link"  />
    <noselfcollision group1="arm_right_4_link" group2="stereo_gazebo_right_camera_link"  />
    <noselfcollision group1="arm_right_4_link" group2="stereo_link"  />
    <noselfcollision group1="arm_right_4_link" group2="wrist_right_ft_link"  />
    <noselfcollision group1="arm_right_4_link" group2="wrist_right_ft_tool_link"  />
    <noselfcollision group1="arm_right_5_link" group2="arm_right_6_link"  />
    <noselfcollision group1="arm_right_5_link" group2="arm_right_7_link"  />
    <noselfcollision group1="arm_right_5_link" group2="arm_right_tool_link"  />
    <noselfcollision group1="arm_right_5_link" group2="back_camera_gazebo_back_camera_link"  />
    <noselfcollision group1="arm_right_5_link" group2="back_camera_link"  />
    <noselfcollision group1="arm_right_5_link" group2="wrist_right_ft_link"  />
    <noselfcollision group1="arm_right_5_link" group2="wrist_right_ft_tool_link"  />
    <noselfcollision group1="arm_right_6_link" group2="arm_right_7_link"  />
    <noselfcollision group1="arm_right_6_link" group2="arm_right_tool_link"  />
    <noselfcollision group1="arm_right_6_link" group2="back_camera_gazebo_back_camera_link"  />
    <noselfcollision group1="arm_right_6_link" group2="back_camera_link"  />
    <noselfcollision group1="arm_right_6_link" group2="wrist_right_ft_link"  />
    <noselfcollision group1="arm_right_6_link" group2="wrist_right_ft_tool_link"  />
    <noselfcollision group1="arm_right_7_link" group2="arm_right_tool_link"  />
    <noselfcollision group1="arm_right_7_link" group2="back_camera_gazebo_back_camera_link"  />
    <noselfcollision group1="arm_right_7_link" group2="back_camera_link"  />
    <noselfcollision group1="arm_right_7_link" group2="stereo_link"  />
    <noselfcollision group1="arm_right_7_link" group2="wrist_right_ft_tool_link"  />
    <noselfcollision group1="arm_right_tool_link" group2="back_camera_gazebo_back_camera_link"  />
    <noselfcollision group1="arm_right_tool_link" group2="back_camera_link"  />
    <noselfcollision group1="arm_right_tool_link" group2="imu_link"  />
    <noselfcollision group1="arm_right_tool_link" group2="stereo_gazebo_left_camera_link"  />
    <noselfcollision group1="arm_right_tool_link" group2="stereo_link"  />
    <noselfcollision group1="arm_right_tool_link" group2="wrist_right_ft_link"  />
    <noselfcollision group1="arm_right_tool_link" group2="wrist_right_ft_tool_link"  />
    <noselfcollision group1="back_camera_gazebo_back_camera_link" group2="back_camera_link"  />
    <noselfcollision group1="back_camera_gazebo_back_camera_link" group2="base_link2"  />
    <noselfcollision group1="back_camera_gazebo_back_camera_link" group2="head_1_link"  />
    <noselfcollision group1="back_camera_gazebo_back_camera_link" group2="head_2_link"  />
    <noselfcollision group1="back_camera_gazebo_back_camera_link" group2="imu_link"  />
    <noselfcollision group1="back_camera_gazebo_back_camera_link" group2="stereo_gazebo_left_camera_link"  />
    <noselfcollision group1="back_camera_gazebo_back_camera_link" group2="stereo_gazebo_right_camera_link"  />
    <noselfcollision group1="back_camera_gazebo_back_camera_link" group2="stereo_link"  />
    <noselfcollision group1="back_camera_gazebo_back_camera_link" group2="torso_1_link"  />
    <noselfcollision group1="back_camera_gazebo_back_camera_link" group2="torso_2_link"  />
    <noselfcollision group1="back_camera_link" group2="base_link2"  />
    <noselfcollision group1="back_camera_link" group2="head_1_link"  />
    <noselfcollision group1="back_camera_link" group2="head_2_link"  />
    <noselfcollision group1="back_camera_link" group2="imu_link"  />
    <noselfcollision group1="back_camera_link" group2="stereo_gazebo_left_camera_link"  />
    <noselfcollision group1="back_camera_link" group2="stereo_gazebo_right_camera_link"  />
    <noselfcollision group1="back_camera_link" group2="stereo_link"  />
    <noselfcollision group1="back_camera_link" group2="torso_1_link"  />
    <noselfcollision group1="back_camera_link" group2="torso_2_link"  />
    <noselfcollision group1="base_link2" group2="head_1_link"  />
    <noselfcollision group1="base_link2" group2="head_2_link"  />
    <noselfcollision group1="base_link2" group2="imu_link"  />
    <noselfcollision group1="base_link2" group2="stereo_gazebo_left_camera_link"  />
    <noselfcollision group1="base_link2" group2="stereo_gazebo_right_camera_link"  />
    <noselfcollision group1="base_link2" group2="stereo_link"  />
    <noselfcollision group1="base_link2" group2="torso_1_link"  />
    <noselfcollision group1="base_link2" group2="torso_2_link"  />
    <noselfcollision group1="head_1_link" group2="head_2_link"  />
    <noselfcollision group1="head_1_link" group2="imu_link"  />
    <noselfcollision group1="head_1_link" group2="stereo_gazebo_left_camera_link"  />
    <noselfcollision group1="head_1_link" group2="stereo_gazebo_right_camera_link"  />
    <noselfcollision group1="head_1_link" group2="stereo_link"  />
    <noselfcollision group1="head_1_link" group2="torso_1_link"  />
    <noselfcollision group1="head_1_link" group2="torso_2_link"  />
    <noselfcollision group1="head_2_link" group2="imu_link"  />
    <noselfcollision group1="head_2_link" group2="stereo_gazebo_left_camera_link"  />
    <noselfcollision group1="head_2_link" group2="stereo_gazebo_right_camera_link"  />
    <noselfcollision group1="head_2_link" group2="stereo_link"  />
    <noselfcollision group1="head_2_link" group2="torso_1_link"  />
    <noselfcollision group1="head_2_link" group2="torso_2_link"  />
    <noselfcollision group1="imu_link" group2="stereo_gazebo_left_camera_link"  />
    <noselfcollision group1="imu_link" group2="stereo_gazebo_right_camera_link"  />
    <noselfcollision group1="imu_link" group2="stereo_link"  />
    <noselfcollision group1="imu_link" group2="torso_1_link"  />
    <noselfcollision group1="imu_link" group2="torso_2_link"  />
    <noselfcollision group1="stereo_gazebo_left_camera_link" group2="stereo_gazebo_right_camera_link"  />
    <noselfcollision group1="stereo_gazebo_left_camera_link" group2="stereo_link"  />
    <noselfcollision group1="stereo_gazebo_left_camera_link" group2="torso_1_link"  />
    <noselfcollision group1="stereo_gazebo_left_camera_link" group2="torso_2_link"  />
    <noselfcollision group1="stereo_gazebo_right_camera_link" group2="stereo_link"  />
    <noselfcollision group1="stereo_gazebo_right_camera_link" group2="torso_1_link"  />
    <noselfcollision group1="stereo_gazebo_right_camera_link" group2="torso_2_link"  />
    <noselfcollision group1="stereo_link" group2="torso_1_link"  />
    <noselfcollision group1="stereo_link" group2="torso_2_link"  />
    <noselfcollision group1="stereo_link" group2="wrist_right_ft_link"  />
    <noselfcollision group1="stereo_link" group2="wrist_right_ft_tool_link"  />
    <noselfcollision group1="torso_1_link" group2="torso_2_link"  />
    <noselfcollision group1="wrist_right_ft_link" group2="wrist_right_ft_tool_link"  />
    <!-- Manually added, to allow hand self-collisions -->
    <noselfcollision group1="wrist_right_ft_link" group2="arm_right_7_link"  />
    <!-- <noselfcollision group1="head_2_link" group2="camera_link"  /> -->
    <noselfcollision group1="wrist_right_ft_tool_link" group2="hand_right_palm_link"  />

</robot>

